Workbook

Sheet Instructions
A1: AI Vendor Risk Assessment Matrix
A2: Supporting tool for the AI Vendor Risk Assessment Procedure v1.0 · Gustavo Rodrigues · CC BY 4.0
A4: Purpose | B4: Assess and compare AI vendors (model APIs, AI-enabled SaaS, hosted open-source models) for one use case, using the same vendor-agnostic criteria.
A5: Step 1 · Tiering | B5: Describe the use case and answer 7 Yes/No questions. The inherent tier (Low / Medium / High) describes the use case, not the vendor.
A6: Step 2 · Assessment | B6: Enter up to 3 vendor names. Score each of the 30 questions from 0 to 3, or N/A, for each vendor. Record evidence in the Notes column.
A7: Step 3 · Knock-outs | B7: At the bottom of the Assessment sheet, mark each knock-out criterion as Pass, Fail or N/A. Any Fail rejects the vendor.
A8: Step 4 · Results | B8: The Results sheet calculates domain scores, overall score, residual risk and the decision for each vendor. Do not edit it.
A9: Scoring scale | B9: 0 = not met or no information · 1 = claimed, no documentation · 2 = met and documented · 3 = met with independent evidence (certification, audit report, signed clause) · N/A = not applicable (record why).
A10: Residual risk | B10: Overall score ≥ 75% = Low · 50% to 74% = Medium · below 50% = High.
A11: Decision rules | B11: Any knock-out Fail → Reject · Residual High → Reject · Residual Medium → Approve with conditions · Residual Low → Approve (Approve (committee) if the tier is High).
A12: Input cells | B12: Yellow cells with blue text are the only cells to edit. All other cells are labels or formulas.
A13: Example data | B13: The workbook is pre-filled with a FICTIONAL example (use case and Vendors A, B, C) so the calculations are visible. Vendors A, B and C do not represent any real company. Clear the yellow cells to start a new assessment.
A14: Procedure | B14: Full method, roles, contract clauses and reassessment rules: procedures/ai-vendor-risk-assessment.md in the ethical-ai-policy repository (github.com/gustavogg99-ctrl/ethical-ai-policy).
A16: Input cell legend | B16: Example input

Sheet Tiering
A1: Step 1 · Inherent Risk Tiering (use case)
A2: Answer Yes or No for the intended use case. The tier applies to every vendor assessed for this use case.
A4: Use case | B4: FICTIONAL EXAMPLE: generative AI assistant that drafts replies to customer service tickets using customer names and order history. Human agents review every reply before it is sent.
A6: ID | B6: Question | C6: Points if Yes | D6: Answer | E6: Points
A7: T-1 | B7: Will the tool process personal data? | C7: 2 | D7: Yes | E7: =IF(D7="Yes",C7,0) -> 2
A8: T-2 | B8: Will it process sensitive personal data (LGPD Art. 5, II) or confidential or regulated business data? | C8: 3 | D8: No | E8: =IF(D8="Yes",C8,0) -> 0
A9: T-3 | B9: Will its outputs be used in decisions that affect individuals (credit, hiring, access to services, benefits)? | C9: 3 | D9: No | E9: =IF(D9="Yes",C9,0) -> 0
A10: T-4 | B10: Will it act autonomously in other systems (agents with write access, automated actions)? | C10: 2 | D10: No | E10: =IF(D10="Yes",C10,0) -> 0
A11: T-5 | B11: Will customers, citizens or other external parties interact directly with it? | C11: 1 | D11: No | E11: =IF(D11="Yes",C11,0) -> 0
A12: T-6 | B12: Would its unavailability stop a business-critical process? | C12: 1 | D12: Yes | E12: =IF(D12="Yes",C12,0) -> 1
A13: T-7 | B13: Will it be used at scale (more than 1,000 users or people affected)? | C13: 1 | D13: Yes | E13: =IF(D13="Yes",C13,0) -> 1
A15: Total points | E15: =SUM(E7:E13) -> 4
A16: Unanswered questions | E16: =COUNTBLANK(D7:D13) -> 0
A17: Inherent tier | E17: =IF(E16>0,"Incomplete",IF(OR(E15>=7,D9="Yes"),"High",IF(E15>=3,"Medium","Low"))) -> Medium
A19: Rules: High = 7 points or more, or T-3 = Yes · Medium = 3 to 6 points · Low = 0 to 2 points.

Sheet Assessment
A1: Steps 2–3 · Vendor Assessment and Knock-out Criteria
A2: Score 0–3 or N/A per vendor. 0 = not met · 1 = claimed only · 2 = documented · 3 = independent evidence.
E3: Vendor names → | F3: Vendor A (fictional) | G3: Vendor B (fictional) | H3: Vendor C (fictional)
A5: ID | B5: Domain | C5: Question | D5: Evidence expected | E5: Weight | F5: =F3 -> Vendor A (fictional) | G5: =G3 -> Vendor B (fictional) | H5: =H3 -> Vendor C (fictional) | I5: Notes / evidence reference
A6: IS-01 | B6: Information Security | C6: Independent security certification or attestation (ISO/IEC 27001, SOC 2 Type II)? | D6: Certificate or audit report and its scope | E6: =INDEX(Results!$B$6:$B$13,MATCH(B6,Results!$A$6:$A$13,0)) -> 0.2 | F6: 3 | G6: 2 | H6: 3
A7: IS-02 | B7: Information Security | C7: Customer data encrypted in transit and at rest? | D7: Security documentation or trust center | E7: =INDEX(Results!$B$6:$B$13,MATCH(B7,Results!$A$6:$A$13,0)) -> 0.2 | F7: 3 | G7: 2 | H7: 2
A8: IS-03 | B8: Information Security | C8: SSO, MFA and role-based access control supported? | D8: Product documentation | E8: =INDEX(Results!$B$6:$B$13,MATCH(B8,Results!$A$6:$A$13,0)) -> 0.2 | F8: 3 | G8: 2 | H8: 3
A9: IS-04 | B9: Information Security | C9: Vulnerability management and regular penetration tests? | D9: Pentest summary or attestation | E9: =INDEX(Results!$B$6:$B$13,MATCH(B9,Results!$A$6:$A$13,0)) -> 0.2 | F9: 2 | G9: 1 | H9: 2
A10: IS-05 | B10: Information Security | C10: Commitment to notify security incidents within a defined timeframe? | D10: Contract or security annex | E10: =INDEX(Results!$B$6:$B$13,MATCH(B10,Results!$A$6:$A$13,0)) -> 0.2 | F10: 3 | G10: 2 | H10: 2
A11: DP-01 | B11: Data Protection & Privacy | C11: Data processing agreement covering LGPD obligations? | D11: Signed or standard DPA | E11: =INDEX(Results!$B$6:$B$13,MATCH(B11,Results!$A$6:$A$13,0)) -> 0.2 | F11: 3 | G11: 2 | H11: 2
A12: DP-02 | B12: Data Protection & Privacy | C12: Data locations disclosed, with a legal mechanism for international transfers? | D12: DPA, data residency documentation | E12: =INDEX(Results!$B$6:$B$13,MATCH(B12,Results!$A$6:$A$13,0)) -> 0.2 | F12: 2 | G12: 2 | H12: 2
A13: DP-03 | B13: Data Protection & Privacy | C13: Prompts, files and outputs excluded from model training by default or by contract? | D13: Contract clause or account setting documentation | E13: =INDEX(Results!$B$6:$B$13,MATCH(B13,Results!$A$6:$A$13,0)) -> 0.2 | F13: 3 | G13: 2 | H13: 0 | I13: Vendor C: terms allow use of customer data for model improvement, no opt-out offered (see KO-2).
A14: DP-04 | B14: Data Protection & Privacy | C14: Configurable retention and verifiable deletion? | D14: Retention policy, deletion procedure | E14: =INDEX(Results!$B$6:$B$13,MATCH(B14,Results!$A$6:$A$13,0)) -> 0.2 | F14: 2 | G14: 2 | H14: 2
A15: DP-05 | B15: Data Protection & Privacy | C15: Subprocessor list available, with notice of changes? | D15: Subprocessor list | E15: =INDEX(Results!$B$6:$B$13,MATCH(B15,Results!$A$6:$A$13,0)) -> 0.2 | F15: 2 | G15: 1 | H15: 2
A16: MG-01 | B16: AI Model Governance | C16: Model or system documentation (intended use, limitations, known risks)? | D16: Model or system card | E16: =INDEX(Results!$B$6:$B$13,MATCH(B16,Results!$A$6:$A$13,0)) -> 0.15 | F16: 2 | G16: 2 | H16: 2
A17: MG-02 | B17: AI Model Governance | C17: Advance notice of model changes, versioning and deprecation? | D17: Change policy, release notes | E17: =INDEX(Results!$B$6:$B$13,MATCH(B17,Results!$A$6:$A$13,0)) -> 0.15 | F17: 2 | G17: 1 | H17: 2
A18: MG-03 | B18: AI Model Governance | C18: Evaluation results for accuracy and performance on relevant tasks? | D18: Evaluation reports, benchmarks | E18: =INDEX(Results!$B$6:$B$13,MATCH(B18,Results!$A$6:$A$13,0)) -> 0.15 | F18: 3 | G18: 1 | H18: 1
A19: MG-04 | B19: AI Model Governance | C19: Underlying foundation model provider disclosed? | D19: Documentation or written confirmation | E19: =INDEX(Results!$B$6:$B$13,MATCH(B19,Results!$A$6:$A$13,0)) -> 0.15 | F19: 2 | G19: 2 | H19: 0 | I19: Vendor C declined to name its foundation model provider.
A20: RA-01 | B20: Responsible AI & Safety | C20: Responsible AI policy or principles published? | D20: Public policy | E20: =INDEX(Results!$B$6:$B$13,MATCH(B20,Results!$A$6:$A$13,0)) -> 0.1 | F20: 2 | G20: 2 | H20: 2
A21: RA-02 | B21: Responsible AI & Safety | C21: Bias and fairness tests documented? | D21: Test reports, model card sections | E21: =INDEX(Results!$B$6:$B$13,MATCH(B21,Results!$A$6:$A$13,0)) -> 0.1 | F21: 2 | G21: 1 | H21: 1
A22: RA-03 | B22: Responsible AI & Safety | C22: Safeguards against harmful content and misuse? | D22: Safety documentation, content filters | E22: =INDEX(Results!$B$6:$B$13,MATCH(B22,Results!$A$6:$A$13,0)) -> 0.1 | F22: 2 | G22: 1 | H22: 2
A23: RA-04 | B23: Responsible AI & Safety | C23: Human oversight supported (review, override, approval steps)? | D23: Product documentation | E23: =INDEX(Results!$B$6:$B$13,MATCH(B23,Results!$A$6:$A$13,0)) -> 0.1 | F23: 2 | G23: 2 | H23: 2
A24: TA-01 | B24: Transparency & Auditability | C24: Usage and audit logs available to the customer? | D24: Admin console, log export or API | E24: =INDEX(Results!$B$6:$B$13,MATCH(B24,Results!$A$6:$A$13,0)) -> 0.1 | F24: 3 | G24: 2 | H24: 2
A25: TA-02 | B25: Transparency & Auditability | C25: Disclosure of AI-generated content to end users supported? | D25: Product documentation | E25: =INDEX(Results!$B$6:$B$13,MATCH(B25,Results!$A$6:$A$13,0)) -> 0.1 | F25: 2 | G25: 1 | H25: 2
A26: TA-03 | B26: Transparency & Auditability | C26: Outputs used in decisions can be explained or justified? | D26: Explainability features, citations | E26: =INDEX(Results!$B$6:$B$13,MATCH(B26,Results!$A$6:$A$13,0)) -> 0.1 | F26: N/A | G26: N/A | H26: N/A | I26: N/A for all vendors: outputs are drafts reviewed by agents; no decisions about individuals (Tiering T-3 = No).
A27: OR-01 | B27: Operational Resilience | C27: Contractual availability SLA? | D27: SLA document | E27: =INDEX(Results!$B$6:$B$13,MATCH(B27,Results!$A$6:$A$13,0)) -> 0.1 | F27: 3 | G27: 2 | H27: 2
A28: OR-02 | B28: Operational Resilience | C28: Business continuity and disaster recovery in place and tested? | D28: BCP/DR summary or attestation | E28: =INDEX(Results!$B$6:$B$13,MATCH(B28,Results!$A$6:$A$13,0)) -> 0.1 | F28: 2 | G28: 2 | H28: 2
A29: OR-03 | B29: Operational Resilience | C29: Data export in a standard format, with an exit plan? | D29: Export features, termination clauses | E29: =INDEX(Results!$B$6:$B$13,MATCH(B29,Results!$A$6:$A$13,0)) -> 0.1 | F29: 2 | G29: 1 | H29: 2
A30: LC-01 | B30: Legal & Contractual | C30: Customer ownership of inputs and outputs defined in contract? | D30: Terms of service | E30: =INDEX(Results!$B$6:$B$13,MATCH(B30,Results!$A$6:$A$13,0)) -> 0.1 | F30: 2 | G30: 2 | H30: 2
A31: LC-02 | B31: Legal & Contractual | C31: IP infringement indemnity for outputs? | D31: Contract clause | E31: =INDEX(Results!$B$6:$B$13,MATCH(B31,Results!$A$6:$A$13,0)) -> 0.1 | F31: 2 | G31: 1 | H31: 2
A32: LC-03 | B32: Legal & Contractual | C32: Audit rights or access to audit reports? | D32: Contract clause | E32: =INDEX(Results!$B$6:$B$13,MATCH(B32,Results!$A$6:$A$13,0)) -> 0.1 | F32: 2 | G32: 1 | H32: 1
A33: LC-04 | B33: Legal & Contractual | C33: Commitment to applicable regulation (LGPD; EU AI Act where relevant)? | D33: Contract, compliance statements | E33: =INDEX(Results!$B$6:$B$13,MATCH(B33,Results!$A$6:$A$13,0)) -> 0.1 | F33: 2 | G33: 2 | H33: 2
A34: VV-01 | B34: Vendor Viability | C34: Sound track record and financial stability? | D34: Company information, references | E34: =INDEX(Results!$B$6:$B$13,MATCH(B34,Results!$A$6:$A$13,0)) -> 0.05 | F34: 3 | G34: 2 | H34: 3
A35: VV-02 | B35: Vendor Viability | C35: Concentration risk and alternatives understood? | D35: Internal market analysis | E35: =INDEX(Results!$B$6:$B$13,MATCH(B35,Results!$A$6:$A$13,0)) -> 0.05 | F35: 2 | G35: 2 | H35: 2
A37: Knock-out criteria · any Fail rejects the vendor regardless of score
A38: ID | B38: Applies to | C38: Criterion | F38: =F3 -> Vendor A (fictional) | G38: =G3 -> Vendor B (fictional) | H38: =H3 -> Vendor C (fictional) | I38: Notes
A39: KO-1 | B39: All tiers, if T-1 = Yes | C39: Vendor does not accept a data processing agreement with LGPD obligations | F39: Pass | G39: Pass | H39: Pass
A40: KO-2 | B40: All tiers | C40: Vendor uses customer data to train or improve models with no opt-out or contractual exclusion | F40: Pass | G40: Pass | H40: Fail | I40: Vendor C fails: see DP-03.
A41: KO-3 | B41: All tiers | C41: Vendor does not commit to notify security incidents affecting customer data | F41: Pass | G41: Pass | H41: Pass
A42: KO-4 | B42: All tiers, if T-1 = Yes | C42: Personal data transferred outside Brazil without an LGPD Art. 33 mechanism | F42: Pass | G42: Pass | H42: Pass
...

Sheet Results
A1: Step 4 · Results and Decision
A2: Calculated automatically from the Tiering and Assessment sheets. Do not edit.
A4: Use case: | B4: =Tiering!B4 -> FICTIONAL EXAMPLE: generative AI assistant that drafts replies to customer service tickets using customer names and order history. Human agents review every reply before it is sent.
A5: Domain | B5: Weight | C5: =Assessment!F3 -> Vendor A (fictional) | D5: =Assessment!G3 -> Vendor B (fictional) | E5: =Assessment!H3 -> Vendor C (fictional) | H5: Calculation (do not edit) | I5: =C5&" contrib." -> Vendor A (fictional) contrib. | J5: =C5&" weight used" -> Vendor A (fictional) weight used | K5: =D5&" contrib." -> Vendor B (fictional) contrib. | L5: =D5&" weight used" -> Vendor B (fictional) weight used | M5: =E5&" contrib." -> Vendor C (fictional) contrib. | N5: =E5&" weight used" -> Vendor C (fictional) weight used
A6: Information Security | B6: 0.2 | C6: =IF(COUNTIFS(Assessment!$B$6:$B$35,$A6,Assessment!F$6:F$35,">=0")=0,"N/A",SUMIFS(Assessment!F$6:F$35,Assessment!$B$6:$B$35,$A6)/(3*COUNTIFS(Assessment!$B$6:$B$35,$A6,Assessment!F$6:F$35,">=0"))) -> 0.93333333 | D6: =IF(COUNTIFS(Assessment!$B$6:$B$35,$A6,Assessment!G$6:G$35,">=0")=0,"N/A",SUMIFS(Assessment!G$6:G$35,Assessment!$B$6:$B$35,$A6)/(3*COUNTIFS(Assessment!$B$6:$B$35,$A6,Assessment!G$6:G$35,">=0"))) -> 0.6 | E6: =IF(COUNTIFS(Assessment!$B$6:$B$35,$A6,Assessment!H$6:H$35,">=0")=0,"N/A",SUMIFS(Assessment!H$6:H$35,Assessment!$B$6:$B$35,$A6)/(3*COUNTIFS(Assessment!$B$6:$B$35,$A6,Assessment!H$6:H$35,">=0"))) -> 0.8 | I6: =IF(ISNUMBER(C6),$B6*C6,0) -> 0.18666667 | J6: =IF(ISNUMBER(C6),$B6,0) -> 0.2 | K6: =IF(ISNUMBER(D6),$B6*D6,0) -> 0.12 | L6: =IF(ISNUMBER(D6),$B6,0) -> 0.2 | M6: =IF(ISNUMBER(E6),$B6*E6,0) -> 0.16 | N6: =IF(ISNUMBER(E6),$B6,0) -> 0.2
A7: Data Protection & Privacy | B7: 0.2 | C7: =IF(COUNTIFS(Assessment!$B$6:$B$35,$A7,Assessment!F$6:F$35,">=0")=0,"N/A",SUMIFS(Assessment!F$6:F$35,Assessment!$B$6:$B$35,$A7)/(3*COUNTIFS(Assessment!$B$6:$B$35,$A7,Assessment!F$6:F$35,">=0"))) -> 0.8 | D7: =IF(COUNTIFS(Assessment!$B$6:$B$35,$A7,Assessment!G$6:G$35,">=0")=0,"N/A",SUMIFS(Assessment!G$6:G$35,Assessment!$B$6:$B$35,$A7)/(3*COUNTIFS(Assessment!$B$6:$B$35,$A7,Assessment!G$6:G$35,">=0"))) -> 0.6 | E7: =IF(COUNTIFS(Assessment!$B$6:$B$35,$A7,Assessment!H$6:H$35,">=0")=0,"N/A",SUMIFS(Assessment!H$6:H$35,Assessment!$B$6:$B$35,$A7)/(3*COUNTIFS(Assessment!$B$6:$B$35,$A7,Assessment!H$6:H$35,">=0"))) -> 0.53333333 | I7: =IF(ISNUMBER(C7),$B7*C7,0) -> 0.16 | J7: =IF(ISNUMBER(C7),$B7,0) -> 0.2 | K7: =IF(ISNUMBER(D7),$B7*D7,0) -> 0.12 | L7: =IF(ISNUMBER(D7),$B7,0) -> 0.2 | M7: =IF(ISNUMBER(E7),$B7*E7,0) -> 0.10666667 | N7: =IF(ISNUMBER(E7),$B7,0) -> 0.2
A8: AI Model Governance | B8: 0.15 | C8: =IF(COUNTIFS(Assessment!$B$6:$B$35,$A8,Assessment!F$6:F$35,">=0")=0,"N/A",SUMIFS(Assessment!F$6:F$35,Assessment!$B$6:$B$35,$A8)/(3*COUNTIFS(Assessment!$B$6:$B$35,$A8,Assessment!F$6:F$35,">=0"))) -> 0.75 | D8: =IF(COUNTIFS(Assessment!$B$6:$B$35,$A8,Assessment!G$6:G$35,">=0")=0,"N/A",SUMIFS(Assessment!G$6:G$35,Assessment!$B$6:$B$35,$A8)/(3*COUNTIFS(Assessment!$B$6:$B$35,$A8,Assessment!G$6:G$35,">=0"))) -> 0.5 | E8: =IF(COUNTIFS(Assessment!$B$6:$B$35,$A8,Assessment!H$6:H$35,">=0")=0,"N/A",SUMIFS(Assessment!H$6:H$35,Assessment!$B$6:$B$35,$A8)/(3*COUNTIFS(Assessment!$B$6:$B$35,$A8,Assessment!H$6:H$35,">=0"))) -> 0.41666667 | I8: =IF(ISNUMBER(C8),$B8*C8,0) -> 0.1125 | J8: =IF(ISNUMBER(C8),$B8,0) -> 0.15 | K8: =IF(ISNUMBER(D8),$B8*D8,0) -> 0.075 | L8: =IF(ISNUMBER(D8),$B8,0) -> 0.15 | M8: =IF(ISNUMBER(E8),$B8*E8,0) -> 0.0625 | N8: =IF(ISNUMBER(E8),$B8,0) -> 0.15
A9: Responsible AI & Safety | B9: 0.1 | C9: =IF(COUNTIFS(Assessment!$B$6:$B$35,$A9,Assessment!F$6:F$35,">=0")=0,"N/A",SUMIFS(Assessment!F$6:F$35,Assessment!$B$6:$B$35,$A9)/(3*COUNTIFS(Assessment!$B$6:$B$35,$A9,Assessment!F$6:F$35,">=0"))) -> 0.66666667 | D9: =IF(COUNTIFS(Assessment!$B$6:$B$35,$A9,Assessment!G$6:G$35,">=0")=0,"N/A",SUMIFS(Assessment!G$6:G$35,Assessment!$B$6:$B$35,$A9)/(3*COUNTIFS(Assessment!$B$6:$B$35,$A9,Assessment!G$6:G$35,">=0"))) -> 0.5 | E9: =IF(COUNTIFS(Assessment!$B$6:$B$35,$A9,Assessment!H$6:H$35,">=0")=0,"N/A",SUMIFS(Assessment!H$6:H$35,Assessment!$B$6:$B$35,$A9)/(3*COUNTIFS(Assessment!$B$6:$B$35,$A9,Assessment!H$6:H$35,">=0"))) -> 0.58333333 | I9: =IF(ISNUMBER(C9),$B9*C9,0) -> 0.066666667 | J9: =IF(ISNUMBER(C9),$B9,0) -> 0.1 | K9: =IF(ISNUMBER(D9),$B9*D9,0) -> 0.05 | L9: =IF(ISNUMBER(D9),$B9,0) -> 0.1 | M9: =IF(ISNUMBER(E9),$B9*E9,0) -> 0.058333333 | N9: =IF(ISNUMBER(E9),$B9,0) -> 0.1
A10: Transparency & Auditability | B10: 0.1 | C10: =IF(COUNTIFS(Assessment!$B$6:$B$35,$A10,Assessment!F$6:F$35,">=0")=0,"N/A",SUMIFS(Assessment!F$6:F$35,Assessment!$B$6:$B$35,$A10)/(3*COUNTIFS(Assessment!$B$6:$B$35,$A10,Assessment!F$6:F$35,">=0"))) -> 0.83333333 | D10: =IF(COUNTIFS(Assessment!$B$6:$B$35,$A10,Assessment!G$6:G$35,">=0")=0,"N/A",SUMIFS(Assessment!G$6:G$35,Assessment!$B$6:$B$35,$A10)/(3*COUNTIFS(Assessment!$B$6:$B$35,$A10,Assessment!G$6:G$35,">=0"))) -> 0.5 | E10: =IF(COUNTIFS(Assessment!$B$6:$B$35,$A10,Assessment!H$6:H$35,">=0")=0,"N/A",SUMIFS(Assessment!H$6:H$35,Assessment!$B$6:$B$35,$A10)/(3*COUNTIFS(Assessment!$B$6:$B$35,$A10,Assessment!H$6:H$35,">=0"))) -> 0.66666667 | I10: =IF(ISNUMBER(C10),$B10*C10,0) -> 0.083333333 | J10: =IF(ISNUMBER(C10),$B10,0) -> 0.1 | K10: =IF(ISNUMBER(D10),$B10*D10,0) -> 0.05 | L10: =IF(ISNUMBER(D10),$B10,0) -> 0.1 | M10: =IF(ISNUMBER(E10),$B10*E10,0) -> 0.066666667 | N10: =IF(ISNUMBER(E10),$B10,0) -> 0.1
A11: Operational Resilience | B11: 0.1 | C11: =IF(COUNTIFS(Assessment!$B$6:$B$35,$A11,Assessment!F$6:F$35,">=0")=0,"N/A",SUMIFS(Assessment!F$6:F$35,Assessment!$B$6:$B$35,$A11)/(3*COUNTIFS(Assessment!$B$6:$B$35,$A11,Assessment!F$6:F$35,">=0"))) -> 0.77777778 | D11: =IF(COUNTIFS(Assessment!$B$6:$B$35,$A11,Assessment!G$6:G$35,">=0")=0,"N/A",SUMIFS(Assessment!G$6:G$35,Assessment!$B$6:$B$35,$A11)/(3*COUNTIFS(Assessment!$B$6:$B$35,$A11,Assessment!G$6:G$35,">=0"))) -> 0.55555556 | E11: =IF(COUNTIFS(Assessment!$B$6:$B$35,$A11,Assessment!H$6:H$35,">=0")=0,"N/A",SUMIFS(Assessment!H$6:H$35,Assessment!$B$6:$B$35,$A11)/(3*COUNTIFS(Assessment!$B$6:$B$35,$A11,Assessment!H$6:H$35,">=0"))) -> 0.66666667 | I11: =IF(ISNUMBER(C11),$B11*C11,0) -> 0.077777778 | J11: =IF(ISNUMBER(C11),$B11,0) -> 0.1 | K11: =IF(ISNUMBER(D11),$B11*D11,0) -> 0.055555556 | L11: =IF(ISNUMBER(D11),$B11,0) -> 0.1 | M11: =IF(ISNUMBER(E11),$B11*E11,0) -> 0.066666667 | N11: =IF(ISNUMBER(E11),$B11,0) -> 0.1
A12: Legal & Contractual | B12: 0.1 | C12: =IF(COUNTIFS(Assessment!$B$6:$B$35,$A12,Assessment!F$6:F$35,">=0")=0,"N/A",SUMIFS(Assessment!F$6:F$35,Assessment!$B$6:$B$35,$A12)/(3*COUNTIFS(Assessment!$B$6:$B$35,$A12,Assessment!F$6:F$35,">=0"))) -> 0.66666667 | D12: =IF(COUNTIFS(Assessment!$B$6:$B$35,$A12,Assessment!G$6:G$35,">=0")=0,"N/A",SUMIFS(Assessment!G$6:G$35,Assessment!$B$6:$B$35,$A12)/(3*COUNTIFS(Assessment!$B$6:$B$35,$A12,Assessment!G$6:G$35,">=0"))) -> 0.5 | E12: =IF(COUNTIFS(Assessment!$B$6:$B$35,$A12,Assessment!H$6:H$35,">=0")=0,"N/A",SUMIFS(Assessment!H$6:H$35,Assessment!$B$6:$B$35,$A12)/(3*COUNTIFS(Assessment!$B$6:$B$35,$A12,Assessment!H$6:H$35,">=0"))) -> 0.58333333 | I12: =IF(ISNUMBER(C12),$B12*C12,0) -> 0.066666667 | J12: =IF(ISNUMBER(C12),$B12,0) -> 0.1 | K12: =IF(ISNUMBER(D12),$B12*D12,0) -> 0.05 | L12: =IF(ISNUMBER(D12),$B12,0) -> 0.1 | M12: =IF(ISNUMBER(E12),$B12*E12,0) -> 0.058333333 | N12: =IF(ISNUMBER(E12),$B12,0) -> 0.1
A13: Vendor Viability | B13: 0.05 | C13: =IF(COUNTIFS(Assessment!$B$6:$B$35,$A13,Assessment!F$6:F$35,">=0")=0,"N/A",SUMIFS(Assessment!F$6:F$35,Assessment!$B$6:$B$35,$A13)/(3*COUNTIFS(Assessment!$B$6:$B$35,$A13,Assessment!F$6:F$35,">=0"))) -> 0.83333333 | D13: =IF(COUNTIFS(Assessment!$B$6:$B$35,$A13,Assessment!G$6:G$35,">=0")=0,"N/A",SUMIFS(Assessment!G$6:G$35,Assessment!$B$6:$B$35,$A13)/(3*COUNTIFS(Assessment!$B$6:$B$35,$A13,Assessment!G$6:G$35,">=0"))) -> 0.66666667 | E13: =IF(COUNTIFS(Assessment!$B$6:$B$35,$A13,Assessment!H$6:H$35,">=0")=0,"N/A",SUMIFS(Assessment!H$6:H$35,Assessment!$B$6:$B$35,$A13)/(3*COUNTIFS(Assessment!$B$6:$B$35,$A13,Assessment!H$6:H$35,">=0"))) -> 0.83333333 | I13: =IF(ISNUMBER(C13),$B13*C13,0) -> 0.041666667 | J13: =IF(ISNUMBER(C13),$B13,0) -> 0.05 | K13: =IF(ISNUMBER(D13),$B13*D13,0) -> 0.033333333 | L13: =IF(ISNUMBER(D13),$B13,0) -> 0.05 | M13: =IF(ISNUMBER(E13),$B13*E13,0) -> 0.041666667 | N13: =IF(ISNUMBER(E13),$B13,0) -> 0.05
A14: Total weight | B14: =SUM(B6:B13) -> 1
A16: Unscored questions | C16: =COUNTBLANK(Assessment!F6:F35) -> 0 | D16: =COUNTBLANK(Assessment!G6:G35) -> 0 | E16: =COUNTBLANK(Assessment!H6:H35) -> 0
A17: Overall score | C17: =IF(C16>0,"Incomplete",IF(SUM(J6:J13)=0,"N/A",SUM(I6:I13)/SUM(J6:J13))) -> 0.79527778 | D17: =IF(D16>0,"Incomplete",IF(SUM(L6:L13)=0,"N/A",SUM(K6:K13)/SUM(L6:L13))) -> 0.55388889 | E17: =IF(E16>0,"Incomplete",IF(SUM(N6:N13)=0,"N/A",SUM(M6:M13)/SUM(N6:N13))) -> 0.62083333
A18: Residual risk | C18: =IF(ISNUMBER(C17),IF(C17>=0.75,"Low",IF(C17>=0.5,"Medium","High")),"—") -> Low | D18: =IF(ISNUMBER(D17),IF(D17>=0.75,"Low",IF(D17>=0.5,"Medium","High")),"—") -> Medium | E18: =IF(ISNUMBER(E17),IF(E17>=0.75,"Low",IF(E17>=0.5,"Medium","High")),"—") -> Medium
A19: Knock-outs failed | C19: =COUNTIF(Assessment!F39:F43,"Fail") -> 0 | D19: =COUNTIF(Assessment!G39:G43,"Fail") -> 0 | E19: =COUNTIF(Assessment!H39:H43,"Fail") -> 1
A20: Knock-outs unanswered | C20: =COUNTBLANK(Assessment!F39:F43) -> 0 | D20: =COUNTBLANK(Assessment!G39:G43) -> 0 | E20: =COUNTBLANK(Assessment!H39:H43) -> 0
A21: Inherent tier (use case) | C21: =Tiering!$E$17 -> Medium | D21: =Tiering!$E$17 -> Medium | E21: =Tiering!$E$17 -> Medium
A22: DECISION | C22: =IF(OR(C16>0,C20>0,C21="Incomplete"),"Incomplete",IF(C19>0,"Reject",IF(C18="High","Reject",IF(C18="Medium","Approve with conditions",IF(C21="High","Approve (committee)","Approve"))))) -> Approve | D22: =IF(OR(D16>0,D20>0,D21="Incomplete"),"Incomplete",IF(D19>0,"Reject",IF(D18="High","Reject",IF(D18="Medium","Approve with conditions",IF(D21="High","Approve (committee)","Approve"))))) -> Approve with conditions | E22: =IF(OR(E16>0,E20>0,E21="Incomplete"),"Incomplete",IF(E19>0,"Reject",IF(E18="High","Reject",IF(E18="Medium","Approve with conditions",IF(E21="High","Approve (committee)","Approve"))))) -> Reject
A23: Decision authority | C23: =IF(C22="Incomplete","—",IF(OR(C21="High",C22="Approve with conditions"),"AI Governance Committee",IF(C21="Medium","Security, Privacy and Legal","Security and Privacy"))) -> Security, Privacy and Legal | D23: =IF(D22="Incomplete","—",IF(OR(D21="High",D22="Approve with conditions"),"AI Governance Committee",IF(D21="Medium","Security, Privacy and Legal","Security and Privacy"))) -> AI Governance Committee | E23: =IF(E22="Incomplete","—",IF(OR(E21="High",E22="Approve with conditions"),"AI Governance Committee",IF(E21="Medium","Security, Privacy and Legal","Security and Privacy"))) -> Security, Privacy and Legal
A24: Reassess within (months) | C24: =IF(OR(C22="Reject",C22="Incomplete"),"—",IF(C22="Approve with conditions",6,IF(C21="High",12,IF(C21="Medium",24,36)))) -> 24 | D24: =IF(OR(D22="Reject",D22="Incomplete"),"—",IF(D22="Approve with conditions",6,IF(D21="High",12,IF(D21="Medium",24,36)))) -> 6 | E24: =IF(OR(E22="Reject",E22="Incomplete"),"—",IF(E22="Approve with conditions",6,IF(E21="High",12,IF(E21="Medium",24,36)))) -> —
A26: Decision rules: any knock-out Fail → Reject · Residual High → Reject · Residual Medium → Approve with conditions (committee sign-off, reassess in 6 months) · Residual Low → Approve, or Approve (committee) when the tier is High.
